Workbook
Name Slicer_Customer_ID: #N/A
Name Slicer_Delivery_Status: #N/A
Name Slicer_Payment_Method: #N/A
Name Slicer_Product_name: #N/A
Name Slicer_Region: #N/A

Sheet 2.1
A3: Sum of Total Amount | B3: Column Labels
A4: Row Labels | B4: Books | C4: Electronics | D4: Fashion | E4: Home | F4: Toys | G4: Grand Total
A5: Central | B5: 84 | C5: 2662 | D5: 210 | E5: 2063 | F5: 437 | G5: 5456
A6: East | B6: 394 | C6: 365 | D6: 711 | E6: 741 | F6: 1424 | G6: 3635
A7: North | B7: 464 | C7: 6522 | D7: 788 | E7: 2131 | F7: 586 | G7: 10491
A8: South | B8: 423 | C8: 3938 | D8: 1032 | E8: 1881 | F8: 43 | G8: 7317
A9: West | B9: 350 | C9: 1722 | D9: 1131 | E9: 4135 | F9: 1021 | G9: 8359
A10: Grand Total | B10: 1715 | C10: 15209 | D10: 3872 | E10: 10951 | F10: 3511 | G10: 35258

Sheet 2.3
A1: Product category | B1: (All)
A2: Payment Method | B2: (All)
A4: Row Labels | B4: Average of Average delivery time
A5: Central | B5: 4.2
A6: East | B6: 4.25
A7: North | B7: 3.625
A8: South | B8: 3.3333333
A9: West | B9: 3.4285714
A10: Grand Total | B10: 3.7647059

Sheet 2,2
A3: Row Labels | B3: Count of Order ID
A4: Cancelled | B4: 30
A5: Delivered | B5: 34
A6: In Transit | B6: 36
A7: Grand Total | B7: 100

Sheet 4.1
A3: Count of Order ID | B3: Column Labels
A4: Row Labels | B4: no | C4: yes | D4: Grand Total
A5: Central | B5: 9 | C5: 5 | D5: 14 | E5: =C5/D5 -> 0.35714286
A6: East | B6: 15 | C6: 3 | D6: 18 | E6: =C6/D6 -> 0.16666667
A7: North | B7: 15 | C7: 10 | D7: 25 | E7: =C7/D7 -> 0.4
A8: South | B8: 16 | C8: 4 | D8: 20 | E8: =C8/D8 -> 0.2
A9: West | B9: 15 | C9: 8 | D9: 23 | E9: =C9/D9 -> 0.34782609
A10: Grand Total | B10: 70 | C10: 30 | D10: 100

Sheet 4.2
A1: Delivery Status | B1: Delivered
A3: Sum of Total Amount
A4: 13656

Sheet total revenue
A3: Sum of Total Amount
A4: 35258

Sheet % fast delivery
B3: Column Labels
B4: fast | C4: na | D4: slow | E4: Grand Total | F4: % fast delivery
A5: Count of Order ID | B5: 11 | C5: 66 | D5: 23 | E5: 100 | F5: =B5/(B5+D5) -> 0.32352941

Sheet Detail1
A3: Order ID | B3: Customer ID | C3: Product ID | D3: Region | E3: Sale Price/Unit | F3: Quantity | G3: Total Amount | H3: Payment Method | I3: Delivery Status | J3: Fulfillment Partner | K3: Order Date | L3: Delivery Date | M3: Cancel Date | N3: Is cancelled | O3: Product category | P3: Average delivery time | Q3: Customer Name | R3: Delivery performance
A4: ORD0001 | B4: CUST021 | C4: PROD012 | D4: North | E4: 44 | F4: 1 | G4: 44 | H4: Apple Pay | I4: Cancelled | J4: DHL | K4: 45291 | M4: 45293 | N4: yes | O4: Home | P4: na | Q4: Zoe Mitchell | R4: na
A5: ORD0096 | B5: CUST017 | C5: PROD015 | D5: North | E5: 21 | F5: 2 | G5: 42 | H5: Amazon Pay | I5: Delivered | J5: UPS | K5: 45116 | L5: 45119 | N5: no | O5: Books | P5: 3 | Q5: Emma King | R5: slow
A6: ORD0094 | B6: CUST013 | C6: PROD004 | D6: North | E6: 62 | F6: 2 | G6: 124 | H6: Credit Card | I6: Cancelled | J6: FedEx | K6: 45265 | M6: 45272 | N6: yes | O6: Toys | P6: na | Q6: Olivia Martinez | R6: na
A7: ORD0004 | B7: CUST044 | C7: PROD013 | D7: North | E7: 196 | F7: 3 | G7: 588 | H7: PayPal | I7: Cancelled | J7: UPS | K7: 45051 | M7: 45057 | N7: yes | O7: Home | P7: na | Q7: Grace Ward | R7: na
A8: ORD0005 | B8: CUST027 | C8: PROD010 | D8: North | E8: 59 | F8: 1 | G8: 59 | H8: PayPal | I8: Delivered | J8: Amazon Logistics | K8: 44959 | L8: 44962 | N8: no | O8: Fashion | P8: 3 | Q8: Hazel Brooks | R8: slow
A9: ORD0006 | B9: CUST009 | C9: PROD010 | D9: North | E9: 58 | F9: 4 | G9: 232 | H9: Amazon Pay | I9: Cancelled | J9: DHL | K9: 45231 | M9: 45232 | N9: yes | O9: Fashion | P9: na | Q9: Jackson Allen | R9: na
A10: ORD0092 | B10: CUST013 | C10: PROD014 | D10: North | E10: 248 | F10: 5 | G10: 1240 | H10: PayPal | I10: Cancelled | J10: UPS | K10: 44978 | M10: 44982 | N10: yes | O10: Electronics | P10: na | Q10: Olivia Martinez | R10: na
A11: ORD0082 | B11: CUST046 | C11: PROD005 | D11: North | E11: 27 | F11: 5 | G11: 135 | H11: Credit Card | I11: Cancelled | J11: Amazon Logistics | K11: 45092 | M11: 45095 | N11: yes | O11: Fashion | P11: na | Q11: Emily Johnson | R11: na
A12: ORD0079 | B12: CUST048 | C12: PROD012 | D12: North | E12: 46 | F12: 1 | G12: 46 | H12: Amazon Pay | I12: In Transit | J12: UPS | K12: 45017 | N12: no | O12: Home | P12: na | Q12: Noah Wilson | R12: na
A13: ORD0076 | B13: CUST023 | C13: PROD019 | D13: North | E13: 43 | F13: 4 | G13: 172 | H13: Debit Card | I13: Delivered | J13: DHL | K13: 45172 | L13: 45178 | N13: no | O13: Fashion | P13: 6 | Q13: Charlotte Reed | R13: slow
A14: ORD0073 | B14: CUST028 | C14: PROD006 | D14: North | E14: 95 | F14: 2 | G14: 190 | H14: PayPal | I14: Cancelled | J14: UPS | K14: 45129 | M14: 45132 | N14: yes | O14: Fashion | P14: na | Q14: Lily Bennett | R14: na
A15: ORD0067 | B15: CUST050 | C15: PROD007 | D15: North | E15: 31 | F15: 4 | G15: 124 | H15: Credit Card | I15: Delivered | J15: UPS | K15: 45135 | L15: 45137 | N15: no | O15: Toys | P15: 2 | Q15: not found | R15: fast
A16: ORD0062 | B16: CUST022 | C16: PROD001 | D16: North | E16: 815 | F16: 4 | G16: 3260 | H16: Credit Card | I16: Delivered | J16: USPS | K16: 45252 | L16: 45259 | N16: no | O16: Electronics | P16: 7 | Q16: Elijah Lewis | R16: slow
A17: ORD0059 | B17: CUST003 | C17: PROD013 | D17: North | E17: 195 | F17: 4 | G17: 780 | H17: PayPal | I17: Cancelled | J17: FedEx | K17: 45018 | M17: 45021 | N17: yes | O17: Home | P17: na | Q17: Ethan Davis | R17: na
A18: ORD0058 | B18: CUST021 | C18: PROD009 | D18: North | E18: 11 | F18: 5 | G18: 55 | H18: Credit Card | I18: In Transit | J18: FedEx | K18: 45054 | N18: no | O18: Books | P18: na | Q18: Zoe Mitchell | R18: na
A19: ORD0054 | B19: CUST018 | C19: PROD004 | D19: North | E19: 64 | F19: 1 | G19: 64 | H19: Apple Pay | I19: Cancelled | J19: USPS | K19: 44991 | M19: 44998 | N19: yes | O19: Toys | P19: na | Q19: Grace Scott | R19: na
A20: ORD0052 | B20: CUST008 | C20: PROD015 | D20: North | E20: 22 | F20: 1 | G20: 22 | H20: Debit Card | I20: Delivered | J20: FedEx | K20: 44956 | L20: 44958 | N20: no | O20: Books | P20: 2 | Q20: Harper Young | R20: fast
A21: ORD0051 | B21: CUST041 | C21: PROD021 | D21: North | E21: 37 | F21: 1 | G21: 37 | H21: Apple Pay | I21: In Transit | J21: UPS | K21: 45201 | N21: no | O21: Home | P21: na | Q21: Jacob Price | R21: na
A22: ORD0047 | B22: CUST041 | C22: PROD020 | D22: North | E22: 104 | F22: 1 | G22: 104 | H22: PayPal | I22: Delivered | J22: Amazon Logistics | K22: 45124 | L22: 45126 | N22: no | O22: Electronics | P22: 2 | Q22: Jacob Price | R22: fast
A23: ORD0020 | B23: CUST025 | C23: PROD001 | D23: North | E23: 813 | F23: 2 | G23: 1626 | H23: Credit Card | I23: In Transit | J23: FedEx | K23: 45028 | N23: no | O23: Electronics | P23: na | Q23: Emma King | R23: na
A24: ORD0046 | B24: CUST039 | C24: PROD017 | D24: North | E24: 73 | F24: 4 | G24: 292 | H24: Credit Card | I24: Delivered | J24: Amazon Logistics | K24: 45264 | L24: 45268 | N24: no | O24: Electronics | P24: 4 | Q24: Logan Ramirez | R24: slow
A25: ORD0038 | B25: CUST028 | C25: PROD007 | D25: North | E25: 32 | F25: 2 | G25: 64 | H25: Debit Card | I25: Cancelled | J25: FedEx | K25: 45160 | M25: 45162 | N25: yes | O25: Toys | P25: na | Q25: Lily Bennett | R25: na
A26: ORD0036 | B26: CUST014 | C26: PROD016 | D26: North | E26: 212 | F26: 3 | G26: 636 | H26: Amazon Pay | I26: In Transit | J26: UPS | K26: 45130 | N26: no | O26: Home | P26: na | Q26: Harper Young | R26: na
A27: ORD0031 | B27: CUST014 | C27: PROD002 | D27: North | E27: 42 | F27: 5 | G27: 210 | H27: Amazon Pay | I27: In Transit | J27: UPS | K27: 45011 | N27: no | O27: Toys | P27: na | Q27: Harper Young | R27: na
A28: ORD0030 | B28: CUST008 | C28: PROD008 | D28: North | E28: 69 | F28: 5 | G28: 345 | H28: Amazon Pay | I28: In Transit | J28: Amazon Logistics | K28: 44971 | N28: no | O28: Books | P28: na | Q28: Harper Young | R28: na

Sheet top 3
A3: Row Labels | B3: Sum of Total Amount
A4: North | B4: 10491
A5: South | B5: 7317
A6: West | B6: 8359
A7: Grand Total | B7: 26167

Sheet highest selling
A3: Row Labels | B3: Count of Total Amount
A4: Leg Set | B4: 8
A5: T-Shirt | B5: 8
A6: Grand Total | B6: 16

Sheet Sheet1
A3: Row Labels | B3: Sum of Total Amount
A4: Central | B4: 5456
A5: East | B5: 3635
A6: North | B6: 10491
A7: South | B7: 7317
A8: West | B8: 8359
A9: Grand Total | B9: 35258

Sheet Sheet8
A1: Row Labels | B1: SALE | C1: HIGH | D1: LOW
A2: Central | B2: 5456 | C2: =IF(B2>=5000,B2,NA()) -> 5456 | D2: =IF(B2<=5000,B2,NA()) -> #N/A
A3: East | B3: 3503 | C3: =IF(B3>=5000,B3,NA()) -> #N/A | D3: =IF(B3<=5000,B3,NA()) -> 3503
A4: North | B4: 10491 | C4: =IF(B4>=5000,B4,NA()) -> 10491 | D4: =IF(B4<=5000,B4,NA()) -> #N/A
A5: South | B5: 6931 | C5: =IF(B5>=5000,B5,NA()) -> 6931 | D5: =IF(B5<=5000,B5,NA()) -> #N/A
A6: West | B6: 8359 | C6: =IF(B6>=5000,B6,NA()) -> 8359 | D6: =IF(B6<=5000,B6,NA()) -> #N/A

Sheet SHEET 2
A3: Row Labels | B3: Sum of Total Amount
A4: Amazon Pay | B4: 4374
A5: Apple Pay | B5: 5452
A6: Credit Card | B6: 9398
A7: Debit Card | B7: 8326
A8: PayPal | B8: 5521
A9: Grand Total | B9: 33071

Sheet Product Master
A1: Product ID | B1: Product Name | C1: Category | D1: Cost Price | E1: Description
A2: PROD001 | B2: Smartphone | C2: Electronics | D2: 749 | E2: Latest model with 5G, dual SIM, and OLED display
A3: PROD002 | B3: Action Figure | C3: Toys | D3: 39 | E3: Collectible superhero action figure for ages 8+
A4: PROD003 | B4: Cookware Set | C4: Home | D4: 129 | E4: Non-stick 5-piece cookware set for daily use
A5: PROD004 | B5: Leg Set | C5: Toys | D5: 59 | E5: 300-piece creative building block toy set
A6: PROD005 | B6: T-Shirt | C6: Fashion | D6: 25 | E6: Cotton t-shirt, available in multiple colors
A7: PROD006 | B7: Shoes | C7: Fashion | D7: 89 | E7: Casual wear shoes for men and women
A8: PROD007 | B8: Puzzle | C8: Toys | D8: 29 | E8: 1000-piece jigsaw puzzle
A9: PROD008 | B9: Textbook | C9: Books | D9: 65 | E9: University-level textbook on computer science
A10: PROD009 | B10: Magazine | C10: Books | D10: 10 | E10: Monthly lifestyle magazine
A11: PROD010 | B11: Jeans | C11: Fashion | D11: 55 | E11: Slim fit denim jeans with stretch
A12: PROD011 | B12: Headphones | C12: Electronics | D12: 159 | E12: Wireless noise-cancelling over-ear headphones
A13: PROD012 | B13: Lamp | C13: Home | D13: 42 | E13: LED desk lamp with dimmable light
... A23: PROD022 | B23: Backpack | C23: Fashion | D23: 60 | E23: Waterproof backpack with laptop compartment

Sheet Sheet4
A3: Row Labels | B3: Sum of Total Amount
A4: Cancelled | B4: 6181
A5: Delivered | B5: 12942
A6: In Transit | B6: 13948
A7: Grand Total | B7: 33071

Sheet Sheet6
A3: Row Labels | B3: Sum of Total Amount
A4: Action Figure | B4: 669
A5: Backpack | B5: 518
A6: Bluetooth Speaker | B6: 731
A7: Cookware Set | B7: 2496
A8: Cookware Set Pro | B8: 5151
A9: Doll House | B9: 1530
A10: Formal Shirt | B10: 995
A11: Gaming Mouse | B11: 1392
A12: Headphones | B12: 172
A13: Jeans | B13: 581
A14: Lamp | B14: 320
A15: Leg Set | B15: 1124
... A26: Grand Total | B26: 33071

Sheet Sheet2
A3: Sum of Total Amount
A4: 35258

Sheet 5.3
A3: Row Labels | B3: Sum of Total Amount
A4: Jan | B4: 1099
A5: Feb | B5: 3712
A6: Mar | B6: 905
A7: Apr | B7: 2637
A8: May | B8: 4940
A9: Jun | B9: 2599
A10: Jul | B10: 3315
A11: Aug | B11: 782
A12: Sep | B12: 1570
A13: Oct | B13: 2920
A14: Nov | B14: 6312
A15: Dec | B15: 4467
A16: Grand Total | B16: 35258

Sheet Sheet3
A3: Row Labels | B3: Sum of Total Amount
A4: Central | B4: 5456
A5: East | B5: 3635
A6: North | B6: 10491
A7: South | B7: 7317
A8: West | B8: 8359
A9: Grand Total | B9: 35258

Sheet Sheet9
A3: Row Labels | B3: Sum of Quantity
A4: CUST004 | B4: 6
A5: CUST006 | B5: 6
A6: CUST007 | B6: 20
A7: CUST009 | B7: 14
A8: CUST011 | B8: 10
A9: CUST013 | B9: 13
A10: CUST014 | B10: 8
A11: CUST015 | B11: 2
A12: CUST016 | B12: 9
A13: CUST017 | B13: 3
A14: CUST018 | B14: 6
A15: CUST019 | B15: 14
... A43: Grand Total | B43: 296

Sheet Orders
A1: Order ID | B1: Customer ID | C1: Product ID | D1: Region | E1: Sale Price/Unit | F1: Quantity | G1: Total Amount | H1: Payment Method | I1: Delivery Status | J1: Fulfillment Partner | K1: Order Date | L1: Delivery Date | M1: Cancel Date | N1: Is cancelled | O1: Product category | P1: Average delivery time | Q1: Customer Name | R1: Delivery performance | S1: Product name
A2: ORD0001 | B2: CUST021 | C2: PROD012 | D2: North | E2: 44 | F2: 1 | G2: 44 | H2: Apple Pay | I2: Cancelled | J2: DHL | K2: 45291 | M2: 45293 | N2: =IF(OR(I2="cancelled",M2<>""),"yes","no") -> yes | O2: =_xlfn.XLOOKUP(C2,'Product Master'!$A$1:$A$23,'Product Master'!$C$1:$C$23) -> Home | P2: =IF(L2<>"",L2-K2,"na") -> na | Q2: =IFERROR(_xlfn.XLOOKUP(B2,'Customer Master'!$A$1:$A$50,'Customer Master'!$B$1:$B$50),"not found") -> Zoe Mitchell | R2: {=_xlfn.IFS(P2="na","na",P2<=2,"fast",P2>2,"slow")} -> na | S2: =_xlfn.XLOOKUP(C2,'Product Master'!$A$1:$A$23,'Product Master'!$B$1:$B$23) -> Lamp
A3: ORD0002 | B3: CUST029 | C3: PROD018 | D3: East | E3: 96 | F3: 4 | G3: 384 | H3: Credit Card | I3: Delivered | J3: DHL | K3: 44979 | L3: 44981 | N3: =IF(OR(I3="cancelled",M3<>""),"yes","no") -> no | O3: =_xlfn.XLOOKUP(C3,'Product Master'!$A$1:$A$23,'Product Master'!$C$1:$C$23) -> Toys | P3: =IF(L3<>"",L3-K3,"na") -> 2 | Q3: =IFERROR(_xlfn.XLOOKUP(B3,'Customer Master'!$A$1:$A$50,'Customer Master'!$B$1:$B$50),"not found") -> Ava White | R3: {=_xlfn.IFS(P3="na","na",P3<=2,"fast",P3>2,"slow")} -> fast | S3: =_xlfn.XLOOKUP(C3,'Product Master'!$A$1:$A$23,'Product Master'!$B$1:$B$23) -> Doll House
A4: ORD0003 | B4: CUST021 | C4: PROD013 | D4: South | E4: 194 | F4: 4 | G4: 776 | H4: Credit Card | I4: In Transit | J4: USPS | K4: 45210 | N4: =IF(OR(I4="cancelled",M4<>""),"yes","no") -> no | O4: =_xlfn.XLOOKUP(C4,'Product Master'!$A$1:$A$23,'Product Master'!$C$1:$C$23) -> Home | P4: =IF(L4<>"",L4-K4,"na") -> na | Q4: =IFERROR(_xlfn.XLOOKUP(B4,'Customer Master'!$A$1:$A$50,'Customer Master'!$B$1:$B$50),"not found") -> Zoe Mitchell | R4: {=_xlfn.IFS(P4="na","na",P4<=2,"fast",P4>2,"slow")} -> na | S4: =_xlfn.XLOOKUP(C4,'Product Master'!$A$1:$A$23,'Product Master'!$B$1:$B$23) -> Vacuum Cleaner
A5: ORD0004 | B5: CUST044 | C5: PROD013 | D5: North | E5: 196 | F5: 3 | G5: 588 | H5: PayPal | I5: Cancelled | J5: UPS | K5: 45051 | M5: 45057 | N5: =IF(OR(I5="cancelled",M5<>""),"yes","no") -> yes | O5: =_xlfn.XLOOKUP(C5,'Product Master'!$A$1:$A$23,'Product Master'!$C$1:$C$23) -> Home | P5: =IF(L5<>"",L5-K5,"na") -> na | Q5: =IFERROR(_xlfn.XLOOKUP(B5,'Customer Master'!$A$1:$A$50,'Customer Master'!$B$1:$B$50),"not found") -> Grace Ward | R5: {=_xlfn.IFS(P5="na","na",P5<=2,"fast",P5>2,"slow")} -> na | S5: =_xlfn.XLOOKUP(C5,'Product Master'!$A$1:$A$23,'Product Master'!$B$1:$B$23) -> Vacuum Cleaner
A6: ORD0005 | B6: CUST027 | C6: PROD010 | D6: North | E6: 59 | F6: 1 | G6: 59 | H6: PayPal | I6: Delivered | J6: Amazon Logistics | K6: 44959 | L6: 44962 | N6: =IF(OR(I6="cancelled",M6<>""),"yes","no") -> no | O6: =_xlfn.XLOOKUP(C6,'Product Master'!$A$1:$A$23,'Product Master'!$C$1:$C$23) -> Fashion | P6: =IF(L6<>"",L6-K6,"na") -> 3 | Q6: =IFERROR(_xlfn.XLOOKUP(B6,'Customer Master'!$A$1:$A$50,'Customer Master'!$B$1:$B$50),"not found") -> Hazel Brooks | R6: {=_xlfn.IFS(P6="na","na",P6<=2,"fast",P6>2,"slow")} -> slow | S6: =_xlfn.XLOOKUP(C6,'Product Master'!$A$1:$A$23,'Product Master'!$B$1:$B$23) -> Jeans
A7: ORD0006 | B7: CUST009 | C7: PROD010 | D7: North | E7: 58 | F7: 4 | G7: 232 | H7: Amazon Pay | I7: Cancelled | J7: DHL | K7: 45231 | M7: 45232 | N7: =IF(OR(I7="cancelled",M7<>""),"yes","no") -> yes | O7: =_xlfn.XLOOKUP(C7,'Product Master'!$A$1:$A$23,'Product Master'!$C$1:$C$23) -> Fashion | P7: =IF(L7<>"",L7-K7,"na") -> na | Q7: =IFERROR(_xlfn.XLOOKUP(B7,'Customer Master'!$A$1:$A$50,'Customer Master'!$B$1:$B$50),"not found") -> Jackson Allen | R7: {=_xlfn.IFS(P7="na","na",P7<=2,"fast",P7>2,"slow")} -> na | S7: =_xlfn.XLOOKUP(C7,'Product Master'!$A$1:$A$23,'Product Master'!$B$1:$B$23) -> Jeans
A8: ORD0007 | B8: CUST042 | C8: PROD020 | D8: Central | E8: 105 | F8: 3 | G8: 315 | H8: Debit Card | I8: Cancelled | J8: DHL | K8: 45152 | M8: 45156 | N8: =IF(OR(I8="cancelled",M8<>""),"yes","no") -> yes | O8: =_xlfn.XLOOKUP(C8,'Product Master'!$A$1:$A$23,'Product Master'!$C$1:$C$23) -> Electronics | P8: =IF(L8<>"",L8-K8,"na") -> na | Q8: =IFERROR(_xlfn.XLOOKUP(B8,'Customer Master'!$A$1:$A$50,'Customer Master'!$B$1:$B$50),"not found") -> Noah Wilson | R8: {=_xlfn.IFS(P8="na","na",P8<=2,"fast",P8>2,"slow")} -> na | S8: =_xlfn.XLOOKUP(C8,'Product Master'!$A$1:$A$23,'Product Master'!$B$1:$B$23) -> Bluetooth Speaker
A9: ORD0008 | B9: CUST019 | C9: PROD021 | D9: West | E9: 37 | F9: 5 | G9: 185 | H9: PayPal | I9: Cancelled | J9: DHL | K9: 45017 | M9: 45022 | N9: =IF(OR(I9="cancelled",M9<>""),"yes","no") -> yes | O9: =_xlfn.XLOOKUP(C9,'Product Master'!$A$1:$A$23,'Product Master'!$C$1:$C$23) -> Home | P9: =IF(L9<>"",L9-K9,"na") -> na | Q9: =IFERROR(_xlfn.XLOOKUP(B9,'Customer Master'!$A$1:$A$50,'Customer Master'!$B$1:$B$50),"not found") -> Ava Robinson | R9: {=_xlfn.IFS(P9="na","na",P9<=2,"fast",P9>2,"slow")} -> na | S9: =_xlfn.XLOOKUP(C9,'Product Master'!$A$1:$A$23,'Product Master'!$B$1:$B$23) -> Wall Clock
A10: ORD0009 | B10: CUST013 | C10: PROD019 | D10: Central | E10: 44 | F10: 2 | G10: 88 | H10: Credit Card | I10: In Transit | J10: Amazon Logistics | K10: 45128 | N10: =IF(OR(I10="cancelled",M10<>""),"yes","no") -> no | O10: =_xlfn.XLOOKUP(C10,'Product Master'!$A$1:$A$23,'Product Master'!$C$1:$C$23) -> Fashion | P10: =IF(L10<>"",L10-K10,"na") -> na | Q10: =IFERROR(_xlfn.XLOOKUP(B10,'Customer Master'!$A$1:$A$50,'Customer Master'!$B$1:$B$50),"not found") -> Olivia Martinez | R10: {=_xlfn.IFS(P10="na","na",P10<=2,"fast",P10>2,"slow")} -> na | S10: =_xlfn.XLOOKUP(C10,'Product Master'!$A$1:$A$23,'Product Master'!$B$1:$B$23) -> Formal Shirt
A11: ORD0010 | B11: CUST019 | C11: PROD003 | D11: South | E11: 141 | F11: 4 | G11: 564 | H11: Debit Card | I11: In Transit | J11: DHL | K11: 45289 | N11: =IF(OR(I11="cancelled",M11<>""),"yes","no") -> no | O11: =_xlfn.XLOOKUP(C11,'Product Master'!$A$1:$A$23,'Product Master'!$C$1:$C$23) -> Home | P11: =IF(L11<>"",L11-K11,"na") -> na | Q11: =IFERROR(_xlfn.XLOOKUP(B11,'Customer Master'!$A$1:$A$50,'Customer Master'!$B$1:$B$50),"not found") -> Ava Robinson | R11: {=_xlfn.IFS(P11="na","na",P11<=2,"fast",P11>2,"slow")} -> na | S11: =_xlfn.XLOOKUP(C11,'Product Master'!$A$1:$A$23,'Product Master'!$B$1:$B$23) -> Cookware Set
A12: ORD0011 | B12: CUST046 | C12: PROD014 | D12: South | E12: 249 | F12: 1 | G12: 249 | H12: Amazon Pay | I12: Cancelled | J12: USPS | K12: 45050 | M12: 45054 | N12: =IF(OR(I12="cancelled",M12<>""),"yes","no") -> yes | O12: =_xlfn.XLOOKUP(C12,'Product Master'!$A$1:$A$23,'Product Master'!$C$1:$C$23) -> Electronics | P12: =IF(L12<>"",L12-K12,"na") -> na | Q12: =IFERROR(_xlfn.XLOOKUP(B12,'Customer Master'!$A$1:$A$50,'Customer Master'!$B$1:$B$50),"not found") -> Emily Johnson | R12: {=_xlfn.IFS(P12="na","na",P12<=2,"fast",P12>2,"slow")} -> na | S12: =_xlfn.XLOOKUP(C12,'Product Master'!$A$1:$A$23,'Product Master'!$B$1:$B$23) -> Smartwatch
A13: ORD0012 | B13: CUST045 | C13: PROD014 | D13: Central | E13: 247 | F13: 3 | G13: 741 | H13: Amazon Pay | I13: In Transit | J13: FedEx | K13: 45132 | N13: =IF(OR(I13="cancelled",M13<>""),"yes","no") -> no | O13: =_xlfn.XLOOKUP(C13,'Product Master'!$A$1:$A$23,'Product Master'!$C$1:$C$23) -> Electronics | P13: =IF(L13<>"",L13-K13,"na") -> na | Q13: =IFERROR(_xlfn.XLOOKUP(B13,'Customer Master'!$A$1:$A$50,'Customer Master'!$B$1:$B$50),"not found") -> Emily Johnson | R13: {=_xlfn.IFS(P13="na","na",P13<=2,"fast",P13>2,"slow")} -> na | S13: =_xlfn.XLOOKUP(C13,'Product Master'!$A$1:$A$23,'Product Master'!$B$1:$B$23) -> Smartwatch
A14: ORD0013 | B14: CUST023 | C14: PROD006 | D14: Central | E14: 96 | F14: 1 | G14: 96 | H14: Apple Pay | I14: Cancelled | J14: Amazon Logistics | K14: 44982 | M14: 44985 | N14: =IF(OR(I14="cancelled",M14<>""),"yes","no") -> yes | O14: =_xlfn.XLOOKUP(C14,'Product Master'!$A$1:$A$23,'Product Master'!$C$1:$C$23) -> Fashion | P14: =IF(L14<>"",L14-K14,"na") -> na | Q14: =IFERROR(_xlfn.XLOOKUP(B14,'Customer Master'!$A$1:$A$50,'Customer Master'!$B$1:$B$50),"not found") -> Charlotte Reed | R14: {=_xlfn.IFS(P14="na","na",P14<=2,"fast",P14>2,"slow")} -> na | S14: =_xlfn.XLOOKUP(C14,'Product Master'!$A$1:$A$23,'Product Master'!$B$1:$B$23) -> Shoes
A15: ORD0014 | B15: CUST033 | C15: PROD017 | D15: West | E15: 74 | F15: 5 | G15: 370 | H15: Apple Pay | I15: Cancelled | J15: Amazon Logistics | K15: 44981 | M15: 44982 | N15: =IF(OR(I15="cancelled",M15<>""),"yes","no") -> yes | O15: =_xlfn.XLOOKUP(C15,'Product Master'!$A$1:$A$23,'Product Master'!$C$1:$C$23) -> Electronics | P15: =IF(L15<>"",L15-K15,"na") -> na | Q15: =IFERROR(_xlfn.XLOOKUP(B15,'Customer Master'!$A$1:$A$50,'Customer Master'!$B$1:$B$50),"not found") -> Hazel Rivera | R15: {=_xlfn.IFS(P15="na","na",P15<=2,"fast",P15>2,"slow")} -> na | S15: =_xlfn.XLOOKUP(C15,'Product Master'!$A$1:$A$23,'Product Master'!$B$1:$B$23) -> Gaming Mouse
A16: ORD0015 | B16: CUST033 | C16: PROD005 | D16: South | E16: 27 | F16: 1 | G16: 27 | H16: Credit Card | I16: Cancelled | J16: Amazon Logistics | K16: 45164 | M16: 45171 | N16: =IF(OR(I16="cancelled",M16<>""),"yes","no") -> yes | O16: =_xlfn.XLOOKUP(C16,'Product Master'!$A$1:$A$23,'Product Master'!$C$1:$C$23) -> Fashion | P16: =IF(L16<>"",L16-K16,"na") -> na | Q16: =IFERROR(_xlfn.XLOOKUP(B16,'Customer Master'!$A$1:$A$50,'Customer Master'!$B$1:$B$50),"not found") -> Hazel Rivera | R16: {=_xlfn.IFS(P16="na","na",P16<=2,"fast",P16>2,"slow")} -> na | S16: =_xlfn.XLOOKUP(C16,'Product Master'!$A$1:$A$23,'Product Master'!$B$1:$B$23) -> T-Shirt
A17: ORD0016 | B17: CUST047 | C17: PROD005 | D17: South | E17: 27 | F17: 3 | G17: 81 | H17: Debit Card | I17: In Transit | J17: Amazon Logistics | K17: 44970 | N17: =IF(OR(I17="cancelled",M17<>""),"yes","no") -> no | O17: =_xlfn.XLOOKUP(C17,'Product Master'!$A$1:$A$23,'Product Master'!$C$1:$C$23) -> Fashion | P17: =IF(L17<>"",L17-K17,"na") -> na | Q17: =IFERROR(_xlfn.XLOOKUP(B17,'Customer Master'!$A$1:$A$50,'Customer Master'!$B$1:$B$50),"not found") -> Scarlett Murphy | R17: {=_xlfn.IFS(P17="na","na",P17<=2,"fast",P17>2,"slow")} -> na | S17: =_xlfn.XLOOKUP(C17,'Product Master'!$A$1:$A$23,'Product Master'!$B$1:$B$23) -> T-Shirt
A18: ORD0017 | B18: CUST045 | C18: PROD015 | D18: East | E18: 21 | F18: 3 | G18: 63 | H18: Credit Card | I18: Delivered | J18: DHL | K18: 45105 | L18: 45108 | N18: =IF(OR(I18="cancelled",M18<>""),"yes","no") -> no | O18: =_xlfn.XLOOKUP(C18,'Product Master'!$A$1:$A$23,'Product Master'!$C$1:$C$23) -> Books | P18: =IF(L18<>"",L18-K18,"na") -> 3 | Q18: =IFERROR(_xlfn.XLOOKUP(B18,'Customer Master'!$A$1:$A$50,'Customer Master'!$B$1:$B$50),"not found") -> Emily Johnson | R18: {=_xlfn.IFS(P18="na","na",P18<=2,"fast",P18>2,"slow")} -> slow | S18: =_xlfn.XLOOKUP(C18,'Product Master'!$A$1:$A$23,'Product Master'!$B$1:$B$23) -> Novel
A19: ORD0018 | B19: CUST011 | C19: PROD008 | D19: West | E19: 70 | F19: 5 | G19: 350 | H19: PayPal | I19: In Transit | J19: Amazon Logistics | K19: 45258 | N19: =IF(OR(I19="cancelled",M19<>""),"yes","no") -> no | O19: =_xlfn.XLOOKUP(C19,'Product Master'!$A$1:$A$23,'Product Master'!$C$1:$C$23) -> Books | P19: =IF(L19<>"",L19-K19,"na") -> na | Q19: =IFERROR(_xlfn.XLOOKUP(B19,'Customer Master'!$A$1:$A$50,'Customer Master'!$B$1:$B$50),"not found") -> Mason Hall | R19: {=_xlfn.IFS(P19="na","na",P19<=2,"fast",P19>2,"slow")} -> na | S19: =_xlfn.XLOOKUP(C19,'Product Master'!$A$1:$A$23,'Product Master'!$B$1:$B$23) -> Textbook
A20: ORD0019 | B20: CUST041 | C20: PROD006 | D20: South | E20: 94 | F20: 4 | G20: 376 | H20: Credit Card | I20: In Transit | J20: USPS | K20: 45163 | N20: =IF(OR(I20="cancelled",M20<>""),"yes","no") -> no | O20: =_xlfn.XLOOKUP(C20,'Product Master'!$A$1:$A$23,'Product Master'!$C$1:$C$23) -> Fashion | P20: =IF(L20<>"",L20-K20,"na") -> na | Q20: =IFERROR(_xlfn.XLOOKUP(B20,'Customer Master'!$A$1:$A$50,'Customer Master'!$B$1:$B$50),"not found") -> Jacob Price | R20: {=_xlfn.IFS(P20="na","na",P20<=2,"fast",P20>2,"slow")} -> na | S20: =_xlfn.XLOOKUP(C20,'Product Master'!$A$1:$A$23,'Product Master'!$B$1:$B$23) -> Shoes
A21: ORD0020 | B21: CUST025 | C21: PROD001 | D21: North | E21: 813 | F21: 2 | G21: 1626 | H21: Credit Card | I21: In Transit | J21: FedEx | K21: 45028 | N21: =IF(OR(I21="cancelled",M21<>""),"yes","no") -> no | O21: =_xlfn.XLOOKUP(C21,'Product Master'!$A$1:$A$23,'Product Master'!$C$1:$C$23) -> Electronics | P21: =IF(L21<>"",L21-K21,"na") -> na | Q21: =IFERROR(_xlfn.XLOOKUP(B21,'Customer Master'!$A$1:$A$50,'Customer Master'!$B$1:$B$50),"not found") -> Emma King | R21: {=_xlfn.IFS(P21="na","na",P21<=2,"fast",P21>2,"slow")} -> na | S21: =_xlfn.XLOOKUP(C21,'Product Master'!$A$1:$A$23,'Product Master'!$B$1:$B$23) -> Smartphone
A22: ORD0021 | B22: CUST013 | C22: PROD015 | D22: Central | E22: 21 | F22: 4 | G22: 84 | H22: PayPal | I22: In Transit | J22: Amazon Logistics | K22: 45201 | N22: =IF(OR(I22="cancelled",M22<>""),"yes","no") -> no | O22: =_xlfn.XLOOKUP(C22,'Product Master'!$A$1:$A$23,'Product Master'!$C$1:$C$23) -> Books | P22: =IF(L22<>"",L22-K22,"na") -> na | Q22: =IFERROR(_xlfn.XLOOKUP(B22,'Customer Master'!$A$1:$A$50,'Customer Master'!$B$1:$B$50),"not found") -> Olivia Martinez | R22: {=_xlfn.IFS(P22="na","na",P22<=2,"fast",P22>2,"slow")} -> na | S22: =_xlfn.XLOOKUP(C22,'Product Master'!$A$1:$A$23,'Product Master'!$B$1:$B$23) -> Novel
A23: ORD0022 | B23: CUST023 | C23: PROD012 | D23: West | E23: 46 | F23: 5 | G23: 230 | H23: PayPal | I23: In Transit | J23: USPS | K23: 45239 | N23: =IF(OR(I23="cancelled",M23<>""),"yes","no") -> no | O23: =_xlfn.XLOOKUP(C23,'Product Master'!$A$1:$A$23,'Product Master'!$C$1:$C$23) -> Home | P23: =IF(L23<>"",L23-K23,"na") -> na | Q23: =IFERROR(_xlfn.XLOOKUP(B23,'Customer Master'!$A$1:$A$50,'Customer Master'!$B$1:$B$50),"not found") -> Charlotte Reed | R23: {=_xlfn.IFS(P23="na","na",P23<=2,"fast",P23>2,"slow")} -> na | S23: =_xlfn.XLOOKUP(C23,'Product Master'!$A$1:$A$23,'Product Master'!$B$1:$B$23) -> Lamp
A24: ORD0023 | B24: CUST016 | C24: PROD010 | D24: West | E24: 58 | F24: 3 | G24: 174 | H24: Amazon Pay | I24: Cancelled | J24: Amazon Logistics | K24: 44970 | M24: 44971 | N24: =IF(OR(I24="cancelled",M24<>""),"yes","no") -> yes | O24: =_xlfn.XLOOKUP(C24,'Product Master'!$A$1:$A$23,'Product Master'!$C$1:$C$23) -> Fashion | P24: =IF(L24<>"",L24-K24,"na") -> na | Q24: =IFERROR(_xlfn.XLOOKUP(B24,'Customer Master'!$A$1:$A$50,'Customer Master'!$B$1:$B$50),"not found") -> Elijah Lewis | R24: {=_xlfn.IFS(P24="na","na",P24<=2,"fast",P24>2,"slow")} -> na | S24: =_xlfn.XLOOKUP(C24,'Product Master'!$A$1:$A$23,'Product Master'!$B$1:$B$23) -> Jeans
A25: ORD0024 | B25: CUST028 | C25: PROD006 | D25: West | E25: 96 | F25: 5 | G25: 480 | H25: Amazon Pay | I25: Delivered | J25: Amazon Logistics | K25: 45232 | L25: 45235 | N25: =IF(OR(I25="cancelled",M25<>""),"yes","no") -> no | O25: =_xlfn.XLOOKUP(C25,'Product Master'!$A$1:$A$23,'Product Master'!$C$1:$C$23) -> Fashion | P25: =IF(L25<>"",L25-K25,"na") -> 3 | Q25: =IFERROR(_xlfn.XLOOKUP(B25,'Customer Master'!$A$1:$A$50,'Customer Master'!$B$1:$B$50),"not found") -> Lily Bennett | R25: {=_xlfn.IFS(P25="na","na",P25<=2,"fast",P25>2,"slow")} -> slow | S25: =_xlfn.XLOOKUP(C25,'Product Master'!$A$1:$A$23,'Product Master'!$B$1:$B$23) -> Shoes
A26: ORD0025 | B26: CUST040 | C26: PROD002 | D26: South | E26: 43 | F26: 1 | G26: 43 | H26: Debit Card | I26: Delivered | J26: Amazon Logistics | K26: 45074 | L26: 45076 | N26: =IF(OR(I26="cancelled",M26<>""),"yes","no") -> no | O26: =_xlfn.XLOOKUP(C26,'Product Master'!$A$1:$A$23,'Product Master'!$C$1:$C$23) -> Toys | P26: =IF(L26<>"",L26-K26,"na") -> 2 | Q26: =IFERROR(_xlfn.XLOOKUP(B26,'Customer Master'!$A$1:$A$50,'Customer Master'!$B$1:$B$50),"not found") -> Benjamin Clark | R26: {=_xlfn.IFS(P26="na","na",P26<=2,"fast",P26>2,"slow")} -> fast | S26: =_xlfn.XLOOKUP(C26,'Product Master'!$A$1:$A$23,'Product Master'!$B$1:$B$23) -> Action Figure
A27: ORD0026 | B27: CUST027 | C27: PROD022 | D27: South | E27: 64 | F27: 4 | G27: 256 | H27: Debit Card | I27: Delivered | J27: USPS | K27: 45214 | L27: 45220 | N27: =IF(OR(I27="cancelled",M27<>""),"yes","no") -> no | O27: =_xlfn.XLOOKUP(C27,'Product Master'!$A$1:$A$23,'Product Master'!$C$1:$C$23) -> Fashion | P27: =IF(L27<>"",L27-K27,"na") -> 6 | Q27: =IFERROR(_xlfn.XLOOKUP(B27,'Customer Master'!$A$1:$A$50,'Customer Master'!$B$1:$B$50),"not found") -> Hazel Brooks | R27: {=_xlfn.IFS(P27="na","na",P27<=2,"fast",P27>2,"slow")} -> slow | S27: =_xlfn.XLOOKUP(C27,'Product Master'!$A$1:$A$23,'Product Master'!$B$1:$B$23) -> Backpack
A28: ORD0027 | B28: CUST018 | C28: PROD008 | D28: South | E28: 70 | F28: 2 | G28: 140 | H28: Amazon Pay | I28: In Transit | J28: Amazon Logistics | K28: 44942 | N28: =IF(OR(I28="cancelled",M28<>""),"yes","no") -> no | O28: =_xlfn.XLOOKUP(C28,'Product Master'!$A$1:$A$23,'Product Master'!$C$1:$C$23) -> Books | P28: =IF(L28<>"",L28-K28,"na") -> na | Q28: =IFERROR(_xlfn.XLOOKUP(B28,'Customer Master'!$A$1:$A$50,'Customer Master'!$B$1:$B$50),"not found") -> Grace Scott | R28: {=_xlfn.IFS(P28="na","na",P28<=2,"fast",P28>2,"slow")} -> na | S28: =_xlfn.XLOOKUP(C28,'Product Master'!$A$1:$A$23,'Product Master'!$B$1:$B$23) -> Textbook
A29: ORD0028 | B29: CUST018 | C29: PROD018 | D29: Central | E29: 97 | F29: 3 | G29: 291 | H29: Credit Card | I29: In Transit | J29: Amazon Logistics | K29: 45208 | N29: =IF(OR(I29="cancelled",M29<>""),"yes","no") -> no | O29: =_xlfn.XLOOKUP(C29,'Product Master'!$A$1:$A$23,'Product Master'!$C$1:$C$23) -> Toys | P29: =IF(L29<>"",L29-K29,"na") -> na | Q29: =IFERROR(_xlfn.XLOOKUP(B29,'Customer Master'!$A$1:$A$50,'Customer Master'!$B$1:$B$50),"not found") -> Grace Scott | R29: {=_xlfn.IFS(P29="na","na",P29<=2,"fast",P29>2,"slow")} -> na | S29: =_xlfn.XLOOKUP(C29,'Product Master'!$A$1:$A$23,'Product Master'!$B$1:$B$23) -> Doll House
A30: ORD0029 | B30: CUST007 | C30: PROD021 | D30: East | E30: 37 | F30: 3 | G30: 111 | H30: Apple Pay | I30: Cancelled | J30: DHL | K30: 45206 | M30: 45209 | N30: =IF(OR(I30="cancelled",M30<>""),"yes","no") -> yes | O30: =_xlfn.XLOOKUP(C30,'Product Master'!$A$1:$A$23,'Product Master'!$C$1:$C$23) -> Home | P30: =IF(L30<>"",L30-K30,"na") -> na | Q30: =IFERROR(_xlfn.XLOOKUP(B30,'Customer Master'!$A$1:$A$50,'Customer Master'!$B$1:$B$50),"not found") -> Liam Walker | R30: {=_xlfn.IFS(P30="na","na",P30<=2,"fast",P30>2,"slow")} -> na | S30: =_xlfn.XLOOKUP(C30,'Product Master'!$A$1:$A$23,'Product Master'!$B$1:$B$23) -> Wall Clock
A31: ORD0030 | B31: CUST008 | C31: PROD008 | D31: North | E31: 69 | F31: 5 | G31: 345 | H31: Amazon Pay | I31: In Transit | J31: Amazon Logistics | K31: 44971 | N31: =IF(OR(I31="cancelled",M31<>""),"yes","no") -> no | O31: =_xlfn.XLOOKUP(C31,'Product Master'!$A$1:$A$23,'Product Master'!$C$1:$C$23) -> Books | P31: =IF(L31<>"",L31-K31,"na") -> na | Q31: =IFERROR(_xlfn.XLOOKUP(B31,'Customer Master'!$A$1:$A$50,'Customer Master'!$B$1:$B$50),"not found") -> Harper Young | R31: {=_xlfn.IFS(P31="na","na",P31<=2,"fast",P31>2,"slow")} -> na | S31: =_xlfn.XLOOKUP(C31,'Product Master'!$A$1:$A$23,'Product Master'!$B$1:$B$23) -> Textbook
A32: ORD0031 | B32: CUST014 | C32: PROD002 | D32: North | E32: 42 | F32: 5 | G32: 210 | H32: Amazon Pay | I32: In Transit | J32: UPS | K32: 45011 | N32: =IF(OR(I32="cancelled",M32<>""),"yes","no") -> no | O32: =_xlfn.XLOOKUP(C32,'Product Master'!$A$1:$A$23,'Product Master'!$C$1:$C$23) -> Toys | P32: =IF(L32<>"",L32-K32,"na") -> na | Q32: =IFERROR(_xlfn.XLOOKUP(B32,'Customer Master'!$A$1:$A$50,'Customer Master'!$B$1:$B$50),"not found") -> Harper Young | R32: {=_xlfn.IFS(P32="na","na",P32<=2,"fast",P32>2,"slow")} -> na | S32: =_xlfn.XLOOKUP(C32,'Product Master'!$A$1:$A$23,'Product Master'!$B$1:$B$23) -> Action Figure
A33: ORD0032 | B33: CUST037 | C33: PROD009 | D33: East | E33: 11 | F33: 5 | G33: 55 | H33: Debit Card | I33: Cancelled | J33: FedEx | K33: 45092 | M33: 45099 | N33: =IF(OR(I33="cancelled",M33<>""),"yes","no") -> yes | O33: =_xlfn.XLOOKUP(C33,'Product Master'!$A$1:$A$23,'Product Master'!$C$1:$C$23) -> Books | P33: =IF(L33<>"",L33-K33,"na") -> na | Q33: =IFERROR(_xlfn.XLOOKUP(B33,'Customer Master'!$A$1:$A$50,'Customer Master'!$B$1:$B$50),"not found") -> Emily Johnson | R33: {=_xlfn.IFS(P33="na","na",P33<=2,"fast",P33>2,"slow")} -> na | S33: =_xlfn.XLOOKUP(C33,'Product Master'!$A$1:$A$23,'Product Master'!$B$1:$B$23) -> Magazine
A34: ORD0033 | B34: CUST016 | C34: PROD005 | D34: South | E34: 27 | F34: 2 | G34: 54 | H34: Apple Pay | I34: Delivered | J34: USPS | K34: 45068 | L34: 45069 | N34: =IF(OR(I34="cancelled",M34<>""),"yes","no") -> no | O34: =_xlfn.XLOOKUP(C34,'Product Master'!$A$1:$A$23,'Product Master'!$C$1:$C$23) -> Fashion | P34: =IF(L34<>"",L34-K34,"na") -> 1 | Q34: =IFERROR(_xlfn.XLOOKUP(B34,'Customer Master'!$A$1:$A$50,'Customer Master'!$B$1:$B$50),"not found") -> Elijah Lewis | R34: {=_xlfn.IFS(P34="na","na",P34<=2,"fast",P34>2,"slow")} -> fast | S34: =_xlfn.XLOOKUP(C34,'Product Master'!$A$1:$A$23,'Product Master'!$B$1:$B$23) -> T-Shirt
A35: ORD0034 | B35: CUST025 | C35: PROD015 | D35: South | E35: 21 | F35: 1 | G35: 21 | H35: Amazon Pay | I35: In Transit | J35: DHL | K35: 45250 | N35: =IF(OR(I35="cancelled",M35<>""),"yes","no") -> no | O35: =_xlfn.XLOOKUP(C35,'Product Master'!$A$1:$A$23,'Product Master'!$C$1:$C$23) -> Books | P35: =IF(L35<>"",L35-K35,"na") -> na | Q35: =IFERROR(_xlfn.XLOOKUP(B35,'Customer Master'!$A$1:$A$50,'Customer Master'!$B$1:$B$50),"not found") -> Emma King | R35: {=_xlfn.IFS(P35="na","na",P35<=2,"fast",P35>2,"slow")} -> na | S35: =_xlfn.XLOOKUP(C35,'Product Master'!$A$1:$A$23,'Product Master'!$B$1:$B$23) -> Novel
A36: ORD0035 | B36: CUST032 | C36: PROD011 | D36: South | E36: 172 | F36: 1 | G36: 172 | H36: PayPal | I36: Delivered | J36: USPS | K36: 45282 | L36: 45286 | N36: =IF(OR(I36="cancelled",M36<>""),"yes","no") -> no | O36: =_xlfn.XLOOKUP(C36,'Product Master'!$A$1:$A$23,'Product Master'!$C$1:$C$23) -> Electronics | P36: =IF(L36<>"",L36-K36,"na") -> 4 | Q36: =IFERROR(_xlfn.XLOOKUP(B36,'Customer Master'!$A$1:$A$50,'Customer Master'!$B$1:$B$50),"not found") -> Luke Gray | R36: {=_xlfn.IFS(P36="na","na",P36<=2,"fast",P36>2,"slow")} -> slow | S36: =_xlfn.XLOOKUP(C36,'Product Master'!$A$1:$A$23,'Product Master'!$B$1:$B$23) -> Headphones
A37: ORD0036 | B37: CUST014 | C37: PROD016 | D37: North | E37: 212 | F37: 3 | G37: 636 | H37: Amazon Pay | I37: In Transit | J37: UPS | K37: 45130 | N37: =IF(OR(I37="cancelled",M37<>""),"yes","no") -> no | O37: =_xlfn.XLOOKUP(C37,'Product Master'!$A$1:$A$23,'Product Master'!$C$1:$C$23) -> Home | P37: =IF(L37<>"",L37-K37,"na") -> na | Q37: =IFERROR(_xlfn.XLOOKUP(B37,'Customer Master'!$A$1:$A$50,'Customer Master'!$B$1:$B$50),"not found") -> Harper Young | R37: {=_xlfn.IFS(P37="na","na",P37<=2,"fast",P37>2,"slow")} -> na | S37: =_xlfn.XLOOKUP(C37,'Product Master'!$A$1:$A$23,'Product Master'!$B$1:$B$23) -> Cookware Set Pro
A38: ORD0037 | B38: CUST044 | C38: PROD002 | D38: East | E38: 41 | F38: 4 | G38: 164 | H38: Credit Card | I38: Delivered | J38: Amazon Logistics | K38: 45216 | L38: 45221 | N38: =IF(OR(I38="cancelled",M38<>""),"yes","no") -> no | O38: =_xlfn.XLOOKUP(C38,'Product Master'!$A$1:$A$23,'Product Master'!$C$1:$C$23) -> Toys | P38: =IF(L38<>"",L38-K38,"na") -> 5 | Q38: =IFERROR(_xlfn.XLOOKUP(B38,'Customer Master'!$A$1:$A$50,'Customer Master'!$B$1:$B$50),"not found") -> Grace Ward | R38: {=_xlfn.IFS(P38="na","na",P38<=2,"fast",P38>2,"slow")} -> slow | S38: =_xlfn.XLOOKUP(C38,'Product Master'!$A$1:$A$23,'Product Master'!$B$1:$B$23) -> Action Figure
A39: ORD0038 | B39: CUST028 | C39: PROD007 | D39: North | E39: 32 | F39: 2 | G39: 64 | H39: Debit Card | I39: Cancelled | J39: FedEx | K39: 45160 | M39: 45162 | N39: =IF(OR(I39="cancelled",M39<>""),"yes","no") -> yes | O39: =_xlfn.XLOOKUP(C39,'Product Master'!$A$1:$A$23,'Product Master'!$C$1:$C$23) -> Toys | P39: =IF(L39<>"",L39-K39,"na") -> na | Q39: =IFERROR(_xlfn.XLOOKUP(B39,'Customer Master'!$A$1:$A$50,'Customer Master'!$B$1:$B$50),"not found") -> Lily Bennett | R39: {=_xlfn.IFS(P39="na","na",P39<=2,"fast",P39>2,"slow")} -> na | S39: =_xlfn.XLOOKUP(C39,'Product Master'!$A$1:$A$23,'Product Master'!$B$1:$B$23) -> Puzzle
A40: ORD0039 | B40: CUST024 | C40: PROD022 | D40: East | E40: 66 | F40: 2 | G40: 132 | H40: Apple Pay | I40: In Transit | J40: DHL | K40: 45262 | N40: =IF(OR(I40="cancelled",M40<>""),"yes","no") -> no | O40: =_xlfn.XLOOKUP(C40,'Product Master'!$A$1:$A$23,'Product Master'!$C$1:$C$23) -> Fashion | P40: =IF(L40<>"",L40-K40,"na") -> na | Q40: =IFERROR(_xlfn.XLOOKUP(B40,'Customer Master'!$A$1:$A$50,'Customer Master'!$B$1:$B$50),"not found") -> Scarlett Murphy | R40: {=_xlfn.IFS(P40="na","na",P40<=2,"fast",P40>2,"slow")} -> na | S40: =_xlfn.XLOOKUP(C40,'Product Master'!$A$1:$A$23,'Product Master'!$B$1:$B$23) -> Backpack
...

Sheet Region Master
A1: Region | B1: Sales Target
A2: Central | B2: 97500
A3: East | B3: 50500
A4: North | B4: 105000
A5: South | B5: 91500
A6: West | B6: 90750

Sheet Customer Master
A1: Customer ID | B1: Customer Name | C1: Customer Type | D1: City | E1: State
A2: CUST001 | B2: James Miller | C2: Business | D2: New York | E2: New York
A3: CUST002 | B3: Emily Johnson | C3: Prime | D3: Seattle | E3: Washington
A4: CUST003 | B4: Ethan Davis | C4: Prime | D4: Austin | E4: Texas
A5: CUST004 | B5: Noah Wilson | C5: Prime | D5: San Francisco | E5: California
A6: CUST005 | B6: Olivia Martinez | C6: Prime | D6: Seattle | E6: Washington
A7: CUST006 | B7: Ava Robinson | C7: Prime | D7: Chicago | E7: Illinois
A8: CUST007 | B8: Liam Walker | C8: Prime | D8: San Francisco | E8: California
A9: CUST008 | B9: Harper Young | C9: Business | D9: Dallas | E9: Texas
A10: CUST009 | B10: Jackson Allen | C10: Business | D10: Seattle | E10: Washington
A11: CUST010 | B11: Charlotte Harris | C11: Prime | D11: Chicago | E11: Illinois
A12: CUST011 | B12: Mason Hall | C12: Business | D12: Miami | E12: Florida
... A50: CUST049 | B50: Hazel Gray | C50: Business | D50: Chicago | E50: Illinois

Sheet DASHBOARD
A1: WORK AND SALES INTELLIGENCE DASHBOARD
AF16: Sum of Total Amount
AF17: 33071
AQ19: Row Labels | AR19: Sum of Total Amount
AQ20: Central | AR20: 5456
AQ21: East | AR21: 3635
AQ22: North | AR22: 9344
AQ23: South | AR23: 7317
AG24: . | AI24: Column Labels | AQ24: West | AR24: 7319
AI25: fast | AJ25: na | AK25: slow | AL25: Grand Total | AM25: % fast delivery | AQ25: Grand Total | AR25: 33071
Z26: TOP 3 PERFORMING REGION | AH26: Count of Order ID | AI26: 11 | AJ26: 66 | AK26: 23 | AL26: 100 | AM26: =AI26/(AI26+AK26) -> 0.32352941
Z27: =AQ20 -> Central
Z28: =AQ21 -> East
Z29: =AQ22 -> North

Sheet Sheet7
A1: fggggf

Sheet Sheet5
A1: BRAINSTORMING REFLECTION
A7: WHAT IS THE MOST SUCCESSFUL PRODUCT CATEGORY IN TERMS OF REVENUE
A8: ELECTRONICS
A10: WHICH REGION HAS THE HIGHEST ORDER CANCELLATION RATE
A11: NORTH
A13: HOW MANY ORDERS DELIVERED IN TWO DAYS
A14: 11
A16: HOW HAS THE X-LOOKUP SIMPLIFIED CROSS -SHEET ANALYSIS
A17: X -LOOKUP CAN MATCH THE EXACT DATA FROM ANOTHER SHEET WHERE DATA STORED
A19: WHAT RECOMMENDATIONS WOULD YOU GIVE TO IMPROVE DELIVERY PERFORMANCE
A20: INSTEAD OF 2 DAYS WE HAVE TO DELIVER IT IN 1 DAY WITH SAFE DELIVERY
